Workbook
Name Slicer_Product_Category: #REF!
Name Slicer_store_region: #REF!

Sheet Dashboard
D2: Sales Performance Dashboard
D4: Oct 2023 – Oct 2025 | Source: Sales_Fact
D6: Total Revenue | F6: Total Orders | H6: Avg Order Value | J6: Unique Customers | L6: Top Region | N6: Top Category
D7: =SUM(Sales_Fact!$O$2:$O$2001) -> 2170969.8 | F7: =COUNTA(Sales_Fact!$A$2:$A$2001) -> 2000 | H7: =AVERAGE(Sales_Fact!$O$2:$O$2001) -> 1085.4849 | J7: =SUMPRODUCT(1/COUNTIF(Sales_Fact!$C$2:$C$2001,Sales_Fact!$C$2:$C$2001)) -> 492 | L7: =INDEX('Pivot and Visualizations '!$A$4:$A$7,MATCH(MAX('Pivot and Visualizations '!$B$4:$B$7),'Pivot and Visualizations '!$B$4:$B$7,0)) -> North | N7: =INDEX('Pivot and Visualizations '!$A$12:$A$16,MATCH(MAX('Pivot and Visualizations '!$B$12:$B$16),'Pivot and Visualizations '!$B$12:$B$16,0)) -> Sports
D10: Key Visualizations

Sheet Customer_Dim
A1: Customer_ID | B1: Name | C1: Age | D1: Gender | E1: City | F1: State | G1: Country | H1: Loyalty_Level | I1: Clean name | J1: Clean city | K1: Clean Country | L1: Clean Customer ID | M1: Clean Loyalty | N1: Age Validation
A2: CUST1000 | B2: sheena bonilla | C2: 55 | D2: Male | E2: Donaldton | F2: North Carolina | G2: USA | I2: =PROPER(TRIM(B2)) -> Sheena Bonilla | J2: =PROPER(TRIM(E2)) -> Donaldton | K2: =IF(OR(G2="USA",G2="usa"),"USA",K5 IF(G2="United States of America","USA","USA")) -> USA | L2: =IF(LEFT(A2,1)="C","CUST"&RIGHT(A2,4),A2) -> CUST1000 | M2: =IF(H2="","Standard",H2) -> Standard | N2: =IF(OR(C2<18,C2>70),"Check Age","Ok") -> Ok
A3: CUST1001 | B3: Eugene Nelson | C3: 26 | D3: Female | E3: Phillipsmouth | F3: North Dakota | G3: USA | H3: Platinum | I3: =PROPER(TRIM(B3)) -> Eugene Nelson | J3: =PROPER(TRIM(E3)) -> Phillipsmouth | K3: =IF(OR(G3="USA",G3="usa"),"USA",K6 IF(G3="United States of America","USA","USA")) -> USA | L3: =IF(LEFT(A3,1)="C","CUST"&RIGHT(A3,4),A3) -> CUST1001 | M3: =IF(H3="","Standard",H3) -> Platinum | N3: =IF(OR(C3<18,C3>70),"Check Age","Ok") -> Ok
A4: CUST1002 | B4: dr. Benjamin Price | C4: 29 | D4: Female | E4: Kylebury | F4: Alabama | G4: USA | H4: Platinum | I4: =PROPER(TRIM(B4)) -> Dr. Benjamin Price | J4: =PROPER(TRIM(E4)) -> Kylebury | K4: =IF(OR(G4="USA",G4="usa"),"USA",K7 IF(G4="United States of America","USA","USA")) -> USA | L4: =IF(LEFT(A4,1)="C","CUST"&RIGHT(A4,4),A4) -> CUST1002 | M4: =IF(H4="","Standard",H4) -> Platinum | N4: =IF(OR(C4<18,C4>70),"Check Age","Ok") -> Ok | P4: Count | Q4: =COUNTA(A:A) -> 501
A5: CUST1003 | B5: jeremy harris | C5: 59 | D5: Female | E5: Thomastown | F5: Ohio | G5: USA | H5: Bronze | I5: =PROPER(TRIM(B5)) -> Jeremy Harris | J5: =PROPER(TRIM(E5)) -> Thomastown | K5: =IF(OR(G5="USA",G5="usa"),"USA",K8 IF(G5="United States of America","USA","USA")) -> USA | L5: =IF(LEFT(A5,1)="C","CUST"&RIGHT(A5,4),A5) -> CUST1003 | M5: =IF(H5="","Standard",H5) -> Bronze | N5: =IF(OR(C5<18,C5>70),"Check Age","Ok") -> Ok | P5: Average | Q5: =ROUNDUP(AVERAGE(C:C),2) -> 41.57
A6: CUST1004 | B6: Caroline Collins | C6: 64 | D6: Female | E6: Nicholasshire | F6: California | G6: USA | H6: Silver | I6: =PROPER(TRIM(B6)) -> Caroline Collins | J6: =PROPER(TRIM(E6)) -> Nicholasshire | K6: =IF(OR(G6="USA",G6="usa"),"USA",K9 IF(G6="United States of America","USA","USA")) -> USA | L6: =IF(LEFT(A6,1)="C","CUST"&RIGHT(A6,4),A6) -> CUST1004 | M6: =IF(H6="","Standard",H6) -> Silver | N6: =IF(OR(C6<18,C6>70),"Check Age","Ok") -> Ok | P6: Male | Q6: =COUNTIF(D:D,"Male") -> 238
A7: CUST1005 | B7: Christine Vaughn | C7: 24 | D7: Male | E7: East Amandamouth | F7: Oregon | G7: USA | H7: Bronze | I7: =PROPER(TRIM(B7)) -> Christine Vaughn | J7: =PROPER(TRIM(E7)) -> East Amandamouth | K7: =IF(OR(G7="USA",G7="usa"),"USA",K10 IF(G7="United States of America","USA","USA")) -> USA | L7: =IF(LEFT(A7,1)="C","CUST"&RIGHT(A7,4),A7) -> CUST1005 | M7: =IF(H7="","Standard",H7) -> Bronze | N7: =IF(OR(C7<18,C7>70),"Check Age","Ok") -> Ok | P7: Female | Q7: =COUNTIF(D:D,"Female") -> 262
A8: CUST1006 | B8: Amber Jackson | C8: 29 | D8: Female | E8: Deborahborough | F8: South Dakota | G8: USA | H8: Platinum | I8: =PROPER(TRIM(B8)) -> Amber Jackson | J8: =PROPER(TRIM(E8)) -> Deborahborough | K8: =IF(OR(G8="USA",G8="usa"),"USA",K11 IF(G8="United States of America","USA","USA")) -> USA | L8: =IF(LEFT(A8,1)="C","CUST"&RIGHT(A8,4),A8) -> CUST1006 | M8: =IF(H8="","Standard",H8) -> Platinum | N8: =IF(OR(C8<18,C8>70),"Check Age","Ok") -> Ok
A9: CUST1007 | B9: Daniel Boyd | C9: 29 | D9: Female | E9: West Pamelafurt | F9: West Virginia | G9: USA | H9: Bronze | I9: =PROPER(TRIM(B9)) -> Daniel Boyd | J9: =PROPER(TRIM(E9)) -> West Pamelafurt | K9: =IF(OR(G9="USA",G9="usa"),"USA",K12 IF(G9="United States of America","USA","USA")) -> USA | L9: =IF(LEFT(A9,1)="C","CUST"&RIGHT(A9,4),A9) -> CUST1007 | M9: =IF(H9="","Standard",H9) -> Bronze | N9: =IF(OR(C9<18,C9>70),"Check Age","Ok") -> Ok
A10: CUST1008 | B10: Melissa Howard | C10: 53 | D10: Female | E10: Maynardton | F10: New Hampshire | G10: USA | H10: Gold | I10: =PROPER(TRIM(B10)) -> Melissa Howard | J10: =PROPER(TRIM(E10)) -> Maynardton | K10: =IF(OR(G10="USA",G10="usa"),"USA",K13 IF(G10="United States of America","USA","USA")) -> USA | L10: =IF(LEFT(A10,1)="C","CUST"&RIGHT(A10,4),A10) -> CUST1008 | M10: =IF(H10="","Standard",H10) -> Gold | N10: =IF(OR(C10<18,C10>70),"Check Age","Ok") -> Ok
A11: CUST1009 | B11: Ms. Maria Leach | C11: 64 | D11: Male | E11: Melissashire | F11: Pennsylvania | G11: USA | H11: Platinum | I11: =PROPER(TRIM(B11)) -> Ms. Maria Leach | J11: =PROPER(TRIM(E11)) -> Melissashire | K11: =IF(OR(G11="USA",G11="usa"),"USA",K14 IF(G11="United States of America","USA","USA")) -> USA | L11: =IF(LEFT(A11,1)="C","CUST"&RIGHT(A11,4),A11) -> CUST1009 | M11: =IF(H11="","Standard",H11) -> Platinum | N11: =IF(OR(C11<18,C11>70),"Check Age","Ok") -> Ok
A12: CUST1010 | B12: Dominic Page | C12: 53 | D12: Male | E12: Port Michaelburgh | F12: Pennsylvania | G12: USA | H12: Bronze | I12: =PROPER(TRIM(B12)) -> Dominic Page | J12: =PROPER(TRIM(E12)) -> Port Michaelburgh | K12: =IF(OR(G12="USA",G12="usa"),"USA",K15 IF(G12="United States of America","USA","USA")) -> USA | L12: =IF(LEFT(A12,1)="C","CUST"&RIGHT(A12,4),A12) -> CUST1010 | M12: =IF(H12="","Standard",H12) -> Bronze | N12: =IF(OR(C12<18,C12>70),"Check Age","Ok") -> Ok
A13: CUST1011 | B13: Brian Lopez | C13: 28 | D13: Female | E13: East Krista | F13: New York | G13: USA | H13: Gold | I13: =PROPER(TRIM(B13)) -> Brian Lopez | J13: =PROPER(TRIM(E13)) -> East Krista | K13: =IF(OR(G13="USA",G13="usa"),"USA",K16 IF(G13="United States of America","USA","USA")) -> USA | L13: =IF(LEFT(A13,1)="C","CUST"&RIGHT(A13,4),A13) -> CUST1011 | M13: =IF(H13="","Standard",H13) -> Gold | N13: =IF(OR(C13<18,C13>70),"Check Age","Ok") -> Ok
A14: CUST1012 | B14: Kenneth Lambert | C14: 55 | D14: Female | E14: North Kathryn | F14: Kansas | G14: USA | H14: Platinum | I14: =PROPER(TRIM(B14)) -> Kenneth Lambert | J14: =PROPER(TRIM(E14)) -> North Kathryn | K14: =IF(OR(G14="USA",G14="usa"),"USA",K17 IF(G14="United States of America","USA","USA")) -> USA | L14: =IF(LEFT(A14,1)="C","CUST"&RIGHT(A14,4),A14) -> CUST1012 | M14: =IF(H14="","Standard",H14) -> Platinum | N14: =IF(OR(C14<18,C14>70),"Check Age","Ok") -> Ok
A15: CUST1013 | B15: Nathan Hernandez | C15: 32 | D15: Female | E15: New Becky | F15: Montana | G15: USA | H15: Silver | I15: =PROPER(TRIM(B15)) -> Nathan Hernandez | J15: =PROPER(TRIM(E15)) -> New Becky | K15: =IF(OR(G15="USA",G15="usa"),"USA",K18 IF(G15="United States of America","USA","USA")) -> USA | L15: =IF(LEFT(A15,1)="C","CUST"&RIGHT(A15,4),A15) -> CUST1013 | M15: =IF(H15="","Standard",H15) -> Silver | N15: =IF(OR(C15<18,C15>70),"Check Age","Ok") -> Ok
A16: CUST1014 | B16: Ashley Cohen | C16: 53 | D16: Female | E16: Lake Kristamouth | F16: Nebraska | G16: USA | H16: Silver | I16: =PROPER(TRIM(B16)) -> Ashley Cohen | J16: =PROPER(TRIM(E16)) -> Lake Kristamouth | K16: =IF(OR(G16="USA",G16="usa"),"USA",K19 IF(G16="United States of America","USA","USA")) -> USA | L16: =IF(LEFT(A16,1)="C","CUST"&RIGHT(A16,4),A16) -> CUST1014 | M16: =IF(H16="","Standard",H16) -> Silver | N16: =IF(OR(C16<18,C16>70),"Check Age","Ok") -> Ok
A17: CUST1015 | B17: Laura Alvarez | C17: 49 | D17: Female | E17: Lawsonhaven | F17: Washington | G17: USA | H17: Platinum | I17: =PROPER(TRIM(B17)) -> Laura Alvarez | J17: =PROPER(TRIM(E17)) -> Lawsonhaven | K17: =IF(OR(G17="USA",G17="usa"),"USA",K20 IF(G17="United States of America","USA","USA")) -> USA | L17: =IF(LEFT(A17,1)="C","CUST"&RIGHT(A17,4),A17) -> CUST1015 | M17: =IF(H17="","Standard",H17) -> Platinum | N17: =IF(OR(C17<18,C17>70),"Check Age","Ok") -> Ok
A18: CUST1016 | B18: John Scott | C18: 24 | D18: Female | E18: South Christopher | F18: Pennsylvania | G18: USA | H18: Bronze | I18: =PROPER(TRIM(B18)) -> John Scott | J18: =PROPER(TRIM(E18)) -> South Christopher | K18: =IF(OR(G18="USA",G18="usa"),"USA",K21 IF(G18="United States of America","USA","USA")) -> USA | L18: =IF(LEFT(A18,1)="C","CUST"&RIGHT(A18,4),A18) -> CUST1016 | M18: =IF(H18="","Standard",H18) -> Bronze | N18: =IF(OR(C18<18,C18>70),"Check Age","Ok") -> Ok
A19: CUST1017 | B19: Adam Cruz | C19: 60 | D19: Female | E19: Brandonville | F19: Georgia | G19: USA | H19: Platinum | I19: =PROPER(TRIM(B19)) -> Adam Cruz | J19: =PROPER(TRIM(E19)) -> Brandonville | K19: =IF(OR(G19="USA",G19="usa"),"USA",K22 IF(G19="United States of America","USA","USA")) -> USA | L19: =IF(LEFT(A19,1)="C","CUST"&RIGHT(A19,4),A19) -> CUST1017 | M19: =IF(H19="","Standard",H19) -> Platinum | N19: =IF(OR(C19<18,C19>70),"Check Age","Ok") -> Ok
A20: CUST1018 | B20: Rhonda Moss | C20: 43 | D20: Male | E20: South William | F20: Kansas | G20: USA | I20: =PROPER(TRIM(B20)) -> Rhonda Moss | J20: =PROPER(TRIM(E20)) -> South William | K20: =IF(OR(G20="USA",G20="usa"),"USA",K23 IF(G20="United States of America","USA","USA")) -> USA | L20: =IF(LEFT(A20,1)="C","CUST"&RIGHT(A20,4),A20) -> CUST1018 | M20: =IF(H20="","Standard",H20) -> Standard | N20: =IF(OR(C20<18,C20>70),"Check Age","Ok") -> Ok
A21: CUST1019 | B21: Michael Torres | C21: 46 | D21: Female | E21: Gonzalezfort | F21: New Jersey | G21: USA | H21: Platinum | I21: =PROPER(TRIM(B21)) -> Michael Torres | J21: =PROPER(TRIM(E21)) -> Gonzalezfort | K21: =IF(OR(G21="USA",G21="usa"),"USA",K24 IF(G21="United States of America","USA","USA")) -> USA | L21: =IF(LEFT(A21,1)="C","CUST"&RIGHT(A21,4),A21) -> CUST1019 | M21: =IF(H21="","Standard",H21) -> Platinum | N21: =IF(OR(C21<18,C21>70),"Check Age","Ok") -> Ok
A22: CUST1020 | B22: Bridget Allen | C22: 59 | D22: Male | E22: Lake Shaneburgh | F22: Delaware | G22: USA | H22: Silver | I22: =PROPER(TRIM(B22)) -> Bridget Allen | J22: =PROPER(TRIM(E22)) -> Lake Shaneburgh | K22: =IF(OR(G22="USA",G22="usa"),"USA",K25 IF(G22="United States of America","USA","USA")) -> USA | L22: =IF(LEFT(A22,1)="C","CUST"&RIGHT(A22,4),A22) -> CUST1020 | M22: =IF(H22="","Standard",H22) -> Silver | N22: =IF(OR(C22<18,C22>70),"Check Age","Ok") -> Ok
A23: CUST1021 | B23: Jeff Martinez | C23: 36 | D23: Female | E23: Smithburgh | F23: Oklahoma | G23: USA | H23: Gold | I23: =PROPER(TRIM(B23)) -> Jeff Martinez | J23: =PROPER(TRIM(E23)) -> Smithburgh | K23: =IF(OR(G23="USA",G23="usa"),"USA",K26 IF(G23="United States of America","USA","USA")) -> USA | L23: =IF(LEFT(A23,1)="C","CUST"&RIGHT(A23,4),A23) -> CUST1021 | M23: =IF(H23="","Standard",H23) -> Gold | N23: =IF(OR(C23<18,C23>70),"Check Age","Ok") -> Ok
A24: CUST1022 | B24: paul fox | C24: 33 | D24: Female | E24: Michaelton | F24: Hawaii | G24: USA | H24: Silver | I24: =PROPER(TRIM(B24)) -> Paul Fox | J24: =PROPER(TRIM(E24)) -> Michaelton | K24: =IF(OR(G24="USA",G24="usa"),"USA",K27 IF(G24="United States of America","USA","USA")) -> USA | L24: =IF(LEFT(A24,1)="C","CUST"&RIGHT(A24,4),A24) -> CUST1022 | M24: =IF(H24="","Standard",H24) -> Silver | N24: =IF(OR(C24<18,C24>70),"Check Age","Ok") -> Ok
A25: CUST1023 | B25: Jonathan Steele | C25: 52 | D25: Female | E25: Molinabury | F25: Oregon | G25: USA | H25: Silver | I25: =PROPER(TRIM(B25)) -> Jonathan Steele | J25: =PROPER(TRIM(E25)) -> Molinabury | K25: =IF(OR(G25="USA",G25="usa"),"USA",K28 IF(G25="United States of America","USA","USA")) -> USA | L25: =IF(LEFT(A25,1)="C","CUST"&RIGHT(A25,4),A25) -> CUST1023 | M25: =IF(H25="","Standard",H25) -> Silver | N25: =IF(OR(C25<18,C25>70),"Check Age","Ok") -> Ok
A26: CUST1024 | B26: Heather Collins | C26: 40 | D26: Male | E26: Rogerschester | F26: Idaho | G26: USA | H26: Platinum | I26: =PROPER(TRIM(B26)) -> Heather Collins | J26: =PROPER(TRIM(E26)) -> Rogerschester | K26: =IF(OR(G26="USA",G26="usa"),"USA",K29 IF(G26="United States of America","USA","USA")) -> USA | L26: =IF(LEFT(A26,1)="C","CUST"&RIGHT(A26,4),A26) -> CUST1024 | M26: =IF(H26="","Standard",H26) -> Platinum | N26: =IF(OR(C26<18,C26>70),"Check Age","Ok") -> Ok
A27: CUST1025 | B27: Diana Taylor | C27: 59 | D27: Female | E27: Vasqueztown | F27: California | G27: USA | H27: Bronze | I27: =PROPER(TRIM(B27)) -> Diana Taylor | J27: =PROPER(TRIM(E27)) -> Vasqueztown | K27: =IF(OR(G27="USA",G27="usa"),"USA",K30 IF(G27="United States of America","USA","USA")) -> USA | L27: =IF(LEFT(A27,1)="C","CUST"&RIGHT(A27,4),A27) -> CUST1025 | M27: =IF(H27="","Standard",H27) -> Bronze | N27: =IF(OR(C27<18,C27>70),"Check Age","Ok") -> Ok
A28: CUST1026 | B28: Amber Carlson | C28: 18 | D28: Female | E28: East Michellemouth | F28: Missouri | G28: USA | H28: Gold | I28: =PROPER(TRIM(B28)) -> Amber Carlson | J28: =PROPER(TRIM(E28)) -> East Michellemouth | K28: =IF(OR(G28="USA",G28="usa"),"USA",K31 IF(G28="United States of America","USA","USA")) -> USA | L28: =IF(LEFT(A28,1)="C","CUST"&RIGHT(A28,4),A28) -> CUST1026 | M28: =IF(H28="","Standard",H28) -> Gold | N28: =IF(OR(C28<18,C28>70),"Check Age","Ok") -> Ok
A29: CUST1027 | B29: Leslie Johnson | C29: 31 | D29: Male | E29: Mollyshire | F29: Utah | G29: USA | I29: =PROPER(TRIM(B29)) -> Leslie Johnson | J29: =PROPER(TRIM(E29)) -> Mollyshire | K29: =IF(OR(G29="USA",G29="usa"),"USA",K32 IF(G29="United States of America","USA","USA")) -> USA | L29: =IF(LEFT(A29,1)="C","CUST"&RIGHT(A29,4),A29) -> CUST1027 | M29: =IF(H29="","Standard",H29) -> Standard | N29: =IF(OR(C29<18,C29>70),"Check Age","Ok") -> Ok
A30: CUST1028 | B30: Joshua Ryan | C30: 27 | D30: Female | E30: New David | F30: New Jersey | G30: USA | H30: Platinum | I30: =PROPER(TRIM(B30)) -> Joshua Ryan | J30: =PROPER(TRIM(E30)) -> New David | K30: =IF(OR(G30="USA",G30="usa"),"USA",K33 IF(G30="United States of America","USA","USA")) -> USA | L30: =IF(LEFT(A30,1)="C","CUST"&RIGHT(A30,4),A30) -> CUST1028 | M30: =IF(H30="","Standard",H30) -> Platinum | N30: =IF(OR(C30<18,C30>70),"Check Age","Ok") -> Ok
A31: CUST1029 | B31: David Arnold | C31: 54 | D31: Female | E31: East Jennifer | F31: California | G31: USA | H31: Silver | I31: =PROPER(TRIM(B31)) -> David Arnold | J31: =PROPER(TRIM(E31)) -> East Jennifer | K31: =IF(OR(G31="USA",G31="usa"),"USA",K34 IF(G31="United States of America","USA","USA")) -> USA | L31: =IF(LEFT(A31,1)="C","CUST"&RIGHT(A31,4),A31) -> CUST1029 | M31: =IF(H31="","Standard",H31) -> Silver | N31: =IF(OR(C31<18,C31>70),"Check Age","Ok") -> Ok
A32: CUST1030 | B32: Jessica Acevedo | C32: 64 | D32: Female | E32: Amybury | F32: Pennsylvania | G32: USA | H32: Bronze | I32: =PROPER(TRIM(B32)) -> Jessica Acevedo | J32: =PROPER(TRIM(E32)) -> Amybury | K32: =IF(OR(G32="USA",G32="usa"),"USA",K35 IF(G32="United States of America","USA","USA")) -> USA | L32: =IF(LEFT(A32,1)="C","CUST"&RIGHT(A32,4),A32) -> CUST1030 | M32: =IF(H32="","Standard",H32) -> Bronze | N32: =IF(OR(C32<18,C32>70),"Check Age","Ok") -> Ok
A33: CUST1031 | B33: Sarah Vance | C33: 41 | D33: Male | E33: Johnsonville | F33: Oregon | G33: USA | H33: Silver | I33: =PROPER(TRIM(B33)) -> Sarah Vance | J33: =PROPER(TRIM(E33)) -> Johnsonville | K33: =IF(OR(G33="USA",G33="usa"),"USA",K36 IF(G33="United States of America","USA","USA")) -> USA | L33: =IF(LEFT(A33,1)="C","CUST"&RIGHT(A33,4),A33) -> CUST1031 | M33: =IF(H33="","Standard",H33) -> Silver | N33: =IF(OR(C33<18,C33>70),"Check Age","Ok") -> Ok
A34: CUST1032 | B34: Mike Jennings | C34: 48 | D34: Female | E34: Fostermouth | F34: Arizona | G34: USA | H34: Gold | I34: =PROPER(TRIM(B34)) -> Mike Jennings | J34: =PROPER(TRIM(E34)) -> Fostermouth | K34: =IF(OR(G34="USA",G34="usa"),"USA",K37 IF(G34="United States of America","USA","USA")) -> USA | L34: =IF(LEFT(A34,1)="C","CUST"&RIGHT(A34,4),A34) -> CUST1032 | M34: =IF(H34="","Standard",H34) -> Gold | N34: =IF(OR(C34<18,C34>70),"Check Age","Ok") -> Ok
A35: CUST1033 | B35: Robert Jones DDS | C35: 25 | D35: Male | E35: Tristanton | F35: Oklahoma | G35: USA | H35: Platinum | I35: =PROPER(TRIM(B35)) -> Robert Jones Dds | J35: =PROPER(TRIM(E35)) -> Tristanton | K35: =IF(OR(G35="USA",G35="usa"),"USA",K38 IF(G35="United States of America","USA","USA")) -> USA | L35: =IF(LEFT(A35,1)="C","CUST"&RIGHT(A35,4),A35) -> CUST1033 | M35: =IF(H35="","Standard",H35) -> Platinum | N35: =IF(OR(C35<18,C35>70),"Check Age","Ok") -> Ok
A36: CUST1034 | B36: Christopher Olson | C36: 27 | D36: Female | E36: West Richard | F36: Maryland | G36: USA | H36: Platinum | I36: =PROPER(TRIM(B36)) -> Christopher Olson | J36: =PROPER(TRIM(E36)) -> West Richard | K36: =IF(OR(G36="USA",G36="usa"),"USA",K39 IF(G36="United States of America","USA","USA")) -> USA | L36: =IF(LEFT(A36,1)="C","CUST"&RIGHT(A36,4),A36) -> CUST1034 | M36: =IF(H36="","Standard",H36) -> Platinum | N36: =IF(OR(C36<18,C36>70),"Check Age","Ok") -> Ok
A37: CUST1035 | B37: Rachel Myers | C37: 52 | D37: Male | E37: Robertberg | F37: North Dakota | G37: USA | H37: Silver | I37: =PROPER(TRIM(B37)) -> Rachel Myers | J37: =PROPER(TRIM(E37)) -> Robertberg | K37: =IF(OR(G37="USA",G37="usa"),"USA",K40 IF(G37="United States of America","USA","USA")) -> USA | L37: =IF(LEFT(A37,1)="C","CUST"&RIGHT(A37,4),A37) -> CUST1035 | M37: =IF(H37="","Standard",H37) -> Silver | N37: =IF(OR(C37<18,C37>70),"Check Age","Ok") -> Ok
A38: CUST1036 | B38: Thomas Phillips | C38: 20 | D38: Female | E38: Luisfurt | F38: Georgia | G38: USA | H38: Gold | I38: =PROPER(TRIM(B38)) -> Thomas Phillips | J38: =PROPER(TRIM(E38)) -> Luisfurt | K38: =IF(OR(G38="USA",G38="usa"),"USA",K41 IF(G38="United States of America","USA","USA")) -> USA | L38: =IF(LEFT(A38,1)="C","CUST"&RIGHT(A38,4),A38) -> CUST1036 | M38: =IF(H38="","Standard",H38) -> Gold | N38: =IF(OR(C38<18,C38>70),"Check Age","Ok") -> Ok
A39: CUST1037 | B39: Christopher Carter | C39: 27 | D39: Female | E39: Brendastad | F39: South Dakota | G39: USA | I39: =PROPER(TRIM(B39)) -> Christopher Carter | J39: =PROPER(TRIM(E39)) -> Brendastad | K39: =IF(OR(G39="USA",G39="usa"),"USA",K42 IF(G39="United States of America","USA","USA")) -> USA | L39: =IF(LEFT(A39,1)="C","CUST"&RIGHT(A39,4),A39) -> CUST1037 | M39: =IF(H39="","Standard",H39) -> Standard | N39: =IF(OR(C39<18,C39>70),"Check Age","Ok") -> Ok
A40: CUST1038 | B40: Deanna Simpson | C40: 35 | D40: Female | E40: Brownport | F40: North Dakota | G40: USA | H40: Bronze | I40: =PROPER(TRIM(B40)) -> Deanna Simpson | J40: =PROPER(TRIM(E40)) -> Brownport | K40: =IF(OR(G40="USA",G40="usa"),"USA",K43 IF(G40="United States of America","USA","USA")) -> USA | L40: =IF(LEFT(A40,1)="C","CUST"&RIGHT(A40,4),A40) -> CUST1038 | M40: =IF(H40="","Standard",H40) -> Bronze | N40: =IF(OR(C40<18,C40>70),"Check Age","Ok") -> Ok
...

Sheet Product_Dim
A1: Product_ID | B1: Product_Name | C1: Category | D1: Sub_Category | E1: Brand | F1: Cost | G1: Stock | H1: Clean Product ID | I1: Clean category | J1: Clean Product Names | K1: Clean cost | L1: Clean stock | M1: Overall Pricing
A2: PROD0 | B2: Brother Laser Printer | C2: Electronics | D2: Computer | E2: Hunt Inc | F2: 112.42 | G2: 416 | H2: =IF(LEFT(A2,2)="PROD16","PROD"&TEXT(MID(A2,3,2),"000"),"PROD"&TEXT(MID(A2,5,2),"000")) -> PROD000 | I2: Electronics | J2: =PROPER(TRIM(B2)) -> Brother Laser Printer | K2: =ROUNDUP(IF(ISBLANK(F2),AVERAGEIF(C:C,C2,F:F),F2),2) -> 112.42 | L2: =ROUNDUP(IF(ISBLANK(G2),AVERAGE(C:C,C2,G:G),G2),0) -> 416 | M2: =K2*L2 -> 46766.72
A3: PROD1 | B3: Men's Graphic T-Shirt | C3: Clothing | D3: Tops | E3: Terry-Moore | F3: 342.56 | G3: 181 | H3: =IF(LEFT(A3,2)="PROD16","PROD"&TEXT(MID(A3,3,2),"000"),"PROD"&TEXT(MID(A3,5,2),"000")) -> PROD001 | I3: Clothing | J3: =PROPER(TRIM(B3)) -> Men'S Graphic T-Shirt | K3: =ROUNDUP(IF(ISBLANK(F3),AVERAGEIF(C:C,C3,F:F),F3),2) -> 342.56 | L3: =ROUNDUP(IF(ISBLANK(G3),AVERAGE(C:C,C3,G:G),G3),0) -> 181 | M3: =K3*L3 -> 62003.36
A4: PROD2 | B4: Women's Casual Hoodie | C4: Clothing | D4: Outerwear | E4: Sims Inc | G4: 352 | H4: =IF(LEFT(A4,2)="PROD16","PROD"&TEXT(MID(A4,3,2),"000"),"PROD"&TEXT(MID(A4,5,2),"000")) -> PROD002 | I4: Clothing | J4: =PROPER(TRIM(B4)) -> Women'S Casual Hoodie | K4: =ROUNDUP(IF(ISBLANK(F4),AVERAGEIF(C:C,C4,F:F),F4),2) -> 265.74 | L4: =ROUNDUP(IF(ISBLANK(G4),AVERAGE(C:C,C4,G:G),G4),0) -> 352 | M4: =K4*L4 -> 93540.48
A5: PROD3 | B5: Men's Running Jacket | C5: Clothing | D5: Outerwear | E5: Pineda Ltd | F5: 364.67 | G5: 452 | H5: =IF(LEFT(A5,2)="PROD16","PROD"&TEXT(MID(A5,3,2),"000"),"PROD"&TEXT(MID(A5,5,2),"000")) -> PROD003 | I5: Clothing | J5: =PROPER(TRIM(B5)) -> Men'S Running Jacket | K5: =ROUNDUP(IF(ISBLANK(F5),AVERAGEIF(C:C,C5,F:F),F5),2) -> 364.67 | L5: =ROUNDUP(IF(ISBLANK(G5),AVERAGE(C:C,C5,G:G),G5),0) -> 452 | M5: =K5*L5 -> 164830.84
A6: PROD4 | B6: Women's Yoga Pants | C6: Clothing | D6: Bottoms | E6: Gonzales-Davis | F6: 306.46 | G6: 487 | H6: =IF(LEFT(A6,2)="PROD16","PROD"&TEXT(MID(A6,3,2),"000"),"PROD"&TEXT(MID(A6,5,2),"000")) -> PROD004 | I6: Clothing | J6: =PROPER(TRIM(B6)) -> Women'S Yoga Pants | K6: =ROUNDUP(IF(ISBLANK(F6),AVERAGEIF(C:C,C6,F:F),F6),2) -> 306.46 | L6: =ROUNDUP(IF(ISBLANK(G6),AVERAGE(C:C,C6,G:G),G6),0) -> 487 | M6: =K6*L6 -> 149246.02
A7: PROD5 | B7: Men's Leather Belt | C7: Clothing | D7: Accessories | E7: Baldwin, Garza and Gonzalez | F7: 261 | G7: 59 | H7: =IF(LEFT(A7,2)="PROD16","PROD"&TEXT(MID(A7,3,2),"000"),"PROD"&TEXT(MID(A7,5,2),"000")) -> PROD005 | I7: Clothing | J7: =PROPER(TRIM(B7)) -> Men'S Leather Belt | K7: =ROUNDUP(IF(ISBLANK(F7),AVERAGEIF(C:C,C7,F:F),F7),2) -> 261 | L7: =ROUNDUP(IF(ISBLANK(G7),AVERAGE(C:C,C7,G:G),G7),0) -> 59 | M7: =K7*L7 -> 15399
A8: PROD6 | B8: Herbal Face Moisturizer | C8: Beauty | D8: Skincare | E8: Davidson PLC | F8: 312.8 | G8: 350 | H8: =IF(LEFT(A8,2)="PROD16","PROD"&TEXT(MID(A8,3,2),"000"),"PROD"&TEXT(MID(A8,5,2),"000")) -> PROD006 | I8: Beauty | J8: =PROPER(TRIM(B8)) -> Herbal Face Moisturizer | K8: =ROUNDUP(IF(ISBLANK(F8),AVERAGEIF(C:C,C8,F:F),F8),2) -> 312.8 | L8: =ROUNDUP(IF(ISBLANK(G8),AVERAGE(C:C,C8,G:G),G8),0) -> 350 | M8: =K8*L8 -> 109480
A9: PROD7 | B9: LED Table Lamp | C9: Home | D9: Lighting | E9: Harrell LLC | F9: 218.86 | G9: 170 | H9: =IF(LEFT(A9,2)="PROD16","PROD"&TEXT(MID(A9,3,2),"000"),"PROD"&TEXT(MID(A9,5,2),"000")) -> PROD007 | I9: Home | J9: =PROPER(TRIM(B9)) -> Led Table Lamp | K9: =ROUNDUP(IF(ISBLANK(F9),AVERAGEIF(C:C,C9,F:F),F9),2) -> 218.86 | L9: =ROUNDUP(IF(ISBLANK(G9),AVERAGE(C:C,C9,G:G),G9),0) -> 170 | M9: =K9*L9 -> 37206.2
A10: PROD8 | B10: Wireless Bluetooth Earbuds | C10: Electronics | D10: Audio | E10: Perez-Johnston | F10: 439.07 | G10: 142 | H10: =IF(LEFT(A10,2)="PROD16","PROD"&TEXT(MID(A10,3,2),"000"),"PROD"&TEXT(MID(A10,5,2),"000")) -> PROD008 | I10: Electronics | J10: =PROPER(TRIM(B10)) -> Wireless Bluetooth Earbuds | K10: =ROUNDUP(IF(ISBLANK(F10),AVERAGEIF(C:C,C10,F:F),F10),2) -> 439.07 | L10: =ROUNDUP(IF(ISBLANK(G10),AVERAGE(C:C,C10,G:G),G10),0) -> 142 | M10: =K10*L10 -> 62347.94
A11: PROD9 | B11: Adjustable Dumbbell Set | C11: Sports | D11: Fitness | E11: Hill PLC | F11: 495.72 | G11: 323 | H11: =IF(LEFT(A11,2)="PROD16","PROD"&TEXT(MID(A11,3,2),"000"),"PROD"&TEXT(MID(A11,5,2),"000")) -> PROD009 | I11: Sports | J11: =PROPER(TRIM(B11)) -> Adjustable Dumbbell Set | K11: =ROUNDUP(IF(ISBLANK(F11),AVERAGEIF(C:C,C11,F:F),F11),2) -> 495.72 | L11: =ROUNDUP(IF(ISBLANK(G11),AVERAGE(C:C,C11,G:G),G11),0) -> 323 | M11: =K11*L11 -> 160117.56
A12: PROD10 | B12: Ceramic Kitchen Bowl Set | C12: Home | D12: Kitchen | E12: Hamilton Group | F12: 298.86 | G12: 308 | H12: =IF(LEFT(A12,2)="PROD16","PROD"&TEXT(MID(A12,3,2),"000"),"PROD"&TEXT(MID(A12,5,2),"000")) -> PROD010 | I12: Home | J12: =PROPER(TRIM(B12)) -> Ceramic Kitchen Bowl Set | K12: =ROUNDUP(IF(ISBLANK(F12),AVERAGEIF(C:C,C12,F:F),F12),2) -> 298.86 | L12: =ROUNDUP(IF(ISBLANK(G12),AVERAGE(C:C,C12,G:G),G12),0) -> 308 | M12: =K12*L12 -> 92048.88
A13: PROD11 | B13: HD Smart TV Stick | C13: Electronics | D13: Accessories | E13: Gibson, Hobbs and Weaver | F13: 449.4 | H13: =IF(LEFT(A13,2)="PROD16","PROD"&TEXT(MID(A13,3,2),"000"),"PROD"&TEXT(MID(A13,5,2),"000")) -> PROD011 | I13: Electronics | J13: =PROPER(TRIM(B13)) -> Hd Smart Tv Stick | K13: =ROUNDUP(IF(ISBLANK(F13),AVERAGEIF(C:C,C13,F:F),F13),2) -> 449.4 | L13: =ROUNDUP(IF(ISBLANK(G13),AVERAGE(C:C,C13,G:G),G13),0) -> 274 | M13: =K13*L13 -> 123135.6
A14: PROD12 | B14: Hair Strengthening Shampoo | C14: Beauty | D14: Haircare | E14: Rice LLC | F14: 115.82 | G14: 460 | H14: =IF(LEFT(A14,2)="PROD16","PROD"&TEXT(MID(A14,3,2),"000"),"PROD"&TEXT(MID(A14,5,2),"000")) -> PROD012 | I14: Beauty | J14: =PROPER(TRIM(B14)) -> Hair Strengthening Shampoo | K14: =ROUNDUP(IF(ISBLANK(F14),AVERAGEIF(C:C,C14,F:F),F14),2) -> 115.82 | L14: =ROUNDUP(IF(ISBLANK(G14),AVERAGE(C:C,C14,G:G),G14),0) -> 460 | M14: =K14*L14 -> 53277.2
A15: PROD13 | B15: USB-C Fast Charger | C15: Electronics | D15: Accessories | E15: Dawson-Perkins | F15: 242.23 | G15: 453 | H15: =IF(LEFT(A15,2)="PROD16","PROD"&TEXT(MID(A15,3,2),"000"),"PROD"&TEXT(MID(A15,5,2),"000")) -> PROD013 | I15: Electronics | J15: =PROPER(TRIM(B15)) -> Usb-C Fast Charger | K15: =ROUNDUP(IF(ISBLANK(F15),AVERAGEIF(C:C,C15,F:F),F15),2) -> 242.23 | L15: =ROUNDUP(IF(ISBLANK(G15),AVERAGE(C:C,C15,G:G),G15),0) -> 453 | M15: =K15*L15 -> 109730.19
A16: PROD14 | B16: Decorative Wall Mirror | C16: Home | D16: Decor | E16: Luna, Anderson and Bowman | F16: 48.01 | G16: 439 | H16: =IF(LEFT(A16,2)="PROD16","PROD"&TEXT(MID(A16,3,2),"000"),"PROD"&TEXT(MID(A16,5,2),"000")) -> PROD014 | I16: Home | J16: =PROPER(TRIM(B16)) -> Decorative Wall Mirror | K16: =ROUNDUP(IF(ISBLANK(F16),AVERAGEIF(C:C,C16,F:F),F16),2) -> 48.01 | L16: =ROUNDUP(IF(ISBLANK(G16),AVERAGE(C:C,C16,G:G),G16),0) -> 439 | M16: =K16*L16 -> 21076.39
A17: PROD15 | B17: 4K Home Projector | C17: Electronics | D17: Appliances | E17: Thomas LLC | F17: 465.34 | G17: 301 | H17: =IF(LEFT(A17,2)="PROD16","PROD"&TEXT(MID(A17,3,2),"000"),"PROD"&TEXT(MID(A17,5,2),"000")) -> PROD015 | I17: Electronics | J17: =PROPER(TRIM(B17)) -> 4K Home Projector | K17: =ROUNDUP(IF(ISBLANK(F17),AVERAGEIF(C:C,C17,F:F),F17),2) -> 465.34 | L17: =ROUNDUP(IF(ISBLANK(G17),AVERAGE(C:C,C17,G:G),G17),0) -> 301 | M17: =K17*L17 -> 140067.34
A18: PROD16 | B18: Beard Grooming Kit | C18: Beauty | D18: Grooming | E18: Erickson-Green | F18: 337.42 | G18: 256 | H18: =IF(LEFT(A18,2)="PROD16","PROD"&TEXT(MID(A18,3,2),"000"),"PROD"&TEXT(MID(A18,5,2),"000")) -> PROD016 | I18: Beauty | J18: =PROPER(TRIM(B18)) -> Beard Grooming Kit | K18: =ROUNDUP(IF(ISBLANK(F18),AVERAGEIF(C:C,C18,F:F),F18),2) -> 337.42 | L18: =ROUNDUP(IF(ISBLANK(G18),AVERAGE(C:C,C18,G:G),G18),0) -> 256 | M18: =K18*L18 -> 86379.52
A19: PROD17 | B19: Soccer Training Cone Set | C19: Sports | D19: Accessories | E19: Ford, Murphy and Wilson | F19: 144.53 | G19: 367 | H19: =IF(LEFT(A19,2)="PROD16","PROD"&TEXT(MID(A19,3,2),"000"),"PROD"&TEXT(MID(A19,5,2),"000")) -> PROD017 | I19: Sports | J19: =PROPER(TRIM(B19)) -> Soccer Training Cone Set | K19: =ROUNDUP(IF(ISBLANK(F19),AVERAGEIF(C:C,C19,F:F),F19),2) -> 144.53 | L19: =ROUNDUP(IF(ISBLANK(G19),AVERAGE(C:C,C19,G:G),G19),0) -> 367 | M19: =K19*L19 -> 53042.51
A20: PROD18 | B20: Women's Denim Jeans | C20: Clothing | D20: Bottoms | E20: Guerra-Hendrix | G20: 343 | H20: =IF(LEFT(A20,2)="PROD16","PROD"&TEXT(MID(A20,3,2),"000"),"PROD"&TEXT(MID(A20,5,2),"000")) -> PROD018 | I20: Clothing | J20: =PROPER(TRIM(B20)) -> Women'S Denim Jeans | K20: =ROUNDUP(IF(ISBLANK(F20),AVERAGEIF(C:C,C20,F:F),F20),2) -> 265.74 | L20: =ROUNDUP(IF(ISBLANK(G20),AVERAGE(C:C,C20,G:G),G20),0) -> 343 | M20: =K20*L20 -> 91148.82
A21: PROD19 | B21: Knee Support Brace | C21: Sports | D21: Equipment | E21: May-Reese | F21: 21.34 | G21: 65 | H21: =IF(LEFT(A21,2)="PROD16","PROD"&TEXT(MID(A21,3,2),"000"),"PROD"&TEXT(MID(A21,5,2),"000")) -> PROD019 | I21: Sports | J21: =PROPER(TRIM(B21)) -> Knee Support Brace | K21: =ROUNDUP(IF(ISBLANK(F21),AVERAGEIF(C:C,C21,F:F),F21),2) -> 21.34 | L21: =ROUNDUP(IF(ISBLANK(G21),AVERAGE(C:C,C21,G:G),G21),0) -> 65 | M21: =K21*L21 -> 1387.1
A22: PROD20 | B22: Outdoor Sports Water Bottle | C22: Sports | D22: Accessories | E22: Soto-Ellis | F22: 131.51 | H22: =IF(LEFT(A22,2)="PROD16","PROD"&TEXT(MID(A22,3,2),"000"),"PROD"&TEXT(MID(A22,5,2),"000")) -> PROD020 | I22: Sports | J22: =PROPER(TRIM(B22)) -> Outdoor Sports Water Bottle | K22: =ROUNDUP(IF(ISBLANK(F22),AVERAGEIF(C:C,C22,F:F),F22),2) -> 131.51 | L22: =ROUNDUP(IF(ISBLANK(G22),AVERAGE(C:C,C22,G:G),G22),0) -> 274 | M22: =K22*L22 -> 36033.74
A23: PROD21 | B23: Multi-Purpose Storage Box | C23: Home | D23: Storage | E23: Gardner-Montes | F23: 123.46 | G23: 76 | H23: =IF(LEFT(A23,2)="PROD16","PROD"&TEXT(MID(A23,3,2),"000"),"PROD"&TEXT(MID(A23,5,2),"000")) -> PROD021 | I23: Home | J23: =PROPER(TRIM(B23)) -> Multi-Purpose Storage Box | K23: =ROUNDUP(IF(ISBLANK(F23),AVERAGEIF(C:C,C23,F:F),F23),2) -> 123.46 | L23: =ROUNDUP(IF(ISBLANK(G23),AVERAGE(C:C,C23,G:G),G23),0) -> 76 | M23: =K23*L23 -> 9382.96
A24: PROD22 | B24: Carbon Fiber Tennis Racket | C24: Sports | D24: Equipment | E24: Flores, Pineda and Rodriguez | F24: 484.62 | G24: 432 | H24: =IF(LEFT(A24,2)="PROD16","PROD"&TEXT(MID(A24,3,2),"000"),"PROD"&TEXT(MID(A24,5,2),"000")) -> PROD022 | I24: Sports | J24: =PROPER(TRIM(B24)) -> Carbon Fiber Tennis Racket | K24: =ROUNDUP(IF(ISBLANK(F24),AVERAGEIF(C:C,C24,F:F),F24),2) -> 484.62 | L24: =ROUNDUP(IF(ISBLANK(G24),AVERAGE(C:C,C24,G:G),G24),0) -> 432 | M24: =K24*L24 -> 209355.84
A25: PROD23 | B25: Men's Formal Shirt | C25: Clothing | D25: Tops | E25: Moon, Mora and Santos | G25: 360 | H25: =IF(LEFT(A25,2)="PROD16","PROD"&TEXT(MID(A25,3,2),"000"),"PROD"&TEXT(MID(A25,5,2),"000")) -> PROD023 | I25: Clothing | J25: =PROPER(TRIM(B25)) -> Men'S Formal Shirt | K25: =ROUNDUP(IF(ISBLANK(F25),AVERAGEIF(C:C,C25,F:F),F25),2) -> 265.74 | L25: =ROUNDUP(IF(ISBLANK(G25),AVERAGE(C:C,C25,G:G),G25),0) -> 360 | M25: =K25*L25 -> 95666.4
A26: PROD24 | B26: Foldable Camping Chair | C26: Sports | D26: Outdoor | E26: Cook Ltd | F26: 166.06 | G26: 340 | H26: =IF(LEFT(A26,2)="PROD16","PROD"&TEXT(MID(A26,3,2),"000"),"PROD"&TEXT(MID(A26,5,2),"000")) -> PROD024 | I26: Sports | J26: =PROPER(TRIM(B26)) -> Foldable Camping Chair | K26: =ROUNDUP(IF(ISBLANK(F26),AVERAGEIF(C:C,C26,F:F),F26),2) -> 166.06 | L26: =ROUNDUP(IF(ISBLANK(G26),AVERAGE(C:C,C26,G:G),G26),0) -> 340 | M26: =K26*L26 -> 56460.4
A27: PROD25 | B27: Women's Scarf Set | C27: Clothing | D27: Accessories | E27: Brown and Sons | F27: 174.02 | G27: 268 | H27: =IF(LEFT(A27,2)="PROD16","PROD"&TEXT(MID(A27,3,2),"000"),"PROD"&TEXT(MID(A27,5,2),"000")) -> PROD025 | I27: Clothing | J27: =PROPER(TRIM(B27)) -> Women'S Scarf Set | K27: =ROUNDUP(IF(ISBLANK(F27),AVERAGEIF(C:C,C27,F:F),F27),2) -> 174.02 | L27: =ROUNDUP(IF(ISBLANK(G27),AVERAGE(C:C,C27,G:G),G27),0) -> 268 | M27: =K27*L27 -> 46637.36
A28: PROD26 | B28: Wireless Bluetooth Speaker | C28: Electronics | D28: Audio | E28: Reed-Schmidt | F28: 322.41 | G28: 213 | H28: =IF(LEFT(A28,2)="PROD16","PROD"&TEXT(MID(A28,3,2),"000"),"PROD"&TEXT(MID(A28,5,2),"000")) -> PROD026 | I28: Electronics | J28: =PROPER(TRIM(B28)) -> Wireless Bluetooth Speaker | K28: =ROUNDUP(IF(ISBLANK(F28),AVERAGEIF(C:C,C28,F:F),F28),2) -> 322.41 | L28: =ROUNDUP(IF(ISBLANK(G28),AVERAGE(C:C,C28,G:G),G28),0) -> 213 | M28: =K28*L28 -> 68673.33
A29: PROD27 | B29: Decorative Floor Vase | C29: Home | D29: Decor | E29: Khan, Jones and Paul | G29: 378 | H29: =IF(LEFT(A29,2)="PROD16","PROD"&TEXT(MID(A29,3,2),"000"),"PROD"&TEXT(MID(A29,5,2),"000")) -> PROD027 | I29: Home | J29: =PROPER(TRIM(B29)) -> Decorative Floor Vase | K29: =ROUNDUP(IF(ISBLANK(F29),AVERAGEIF(C:C,C29,F:F),F29),2) -> 234.81 | L29: =ROUNDUP(IF(ISBLANK(G29),AVERAGE(C:C,C29,G:G),G29),0) -> 378 | M29: =K29*L29 -> 88758.18
A30: PROD28 | B30: Sports Stopwatch Timer | C30: Sports | D30: Accessories | E30: Burns-Hansen | F30: 38.76 | G30: 137 | H30: =IF(LEFT(A30,2)="PROD16","PROD"&TEXT(MID(A30,3,2),"000"),"PROD"&TEXT(MID(A30,5,2),"000")) -> PROD028 | I30: Sports | J30: =PROPER(TRIM(B30)) -> Sports Stopwatch Timer | K30: =ROUNDUP(IF(ISBLANK(F30),AVERAGEIF(C:C,C30,F:F),F30),2) -> 38.76 | L30: =ROUNDUP(IF(ISBLANK(G30),AVERAGE(C:C,C30,G:G),G30),0) -> 137 | M30: =K30*L30 -> 5310.12
A31: PROD29 | B31: Fabric Sofa Throw Blanket | C31: Home | D31: Decor | E31: Hoffman Group | F31: 218.48 | G31: 276 | H31: =IF(LEFT(A31,2)="PROD16","PROD"&TEXT(MID(A31,3,2),"000"),"PROD"&TEXT(MID(A31,5,2),"000")) -> PROD029 | I31: Home | J31: =PROPER(TRIM(B31)) -> Fabric Sofa Throw Blanket | K31: =ROUNDUP(IF(ISBLANK(F31),AVERAGEIF(C:C,C31,F:F),F31),2) -> 218.48 | L31: =ROUNDUP(IF(ISBLANK(G31),AVERAGE(C:C,C31,G:G),G31),0) -> 276 | M31: =K31*L31 -> 60300.48
A32: PROD30 | B32: Stainless Steel Cutlery Set | C32: Home | D32: Kitchen | E32: Stevens, Fernandez and Martin | F32: 19.52 | G32: 57 | H32: =IF(LEFT(A32,2)="PROD16","PROD"&TEXT(MID(A32,3,2),"000"),"PROD"&TEXT(MID(A32,5,2),"000")) -> PROD030 | I32: Home | J32: =PROPER(TRIM(B32)) -> Stainless Steel Cutlery Set | K32: =ROUNDUP(IF(ISBLANK(F32),AVERAGEIF(C:C,C32,F:F),F32),2) -> 19.52 | L32: =ROUNDUP(IF(ISBLANK(G32),AVERAGE(C:C,C32,G:G),G32),0) -> 57 | M32: =K32*L32 -> 1112.64
A33: PROD31 | B33: Basketball | C33: Sports | D33: Team Sports | E33: Nolan-Snow | F33: 204.39 | G33: 281 | H33: =IF(LEFT(A33,2)="PROD16","PROD"&TEXT(MID(A33,3,2),"000"),"PROD"&TEXT(MID(A33,5,2),"000")) -> PROD031 | I33: Sports | J33: =PROPER(TRIM(B33)) -> Basketball | K33: =ROUNDUP(IF(ISBLANK(F33),AVERAGEIF(C:C,C33,F:F),F33),2) -> 204.39 | L33: =ROUNDUP(IF(ISBLANK(G33),AVERAGE(C:C,C33,G:G),G33),0) -> 281 | M33: =K33*L33 -> 57433.59
A34: PROD32 | B34: Vitamin C Face Serum | C34: Beauty | D34: Skincare | E34: Griffin Ltd | F34: 283.83 | G34: 244 | H34: =IF(LEFT(A34,2)="PROD16","PROD"&TEXT(MID(A34,3,2),"000"),"PROD"&TEXT(MID(A34,5,2),"000")) -> PROD032 | I34: Beauty | J34: =PROPER(TRIM(B34)) -> Vitamin C Face Serum | K34: =ROUNDUP(IF(ISBLANK(F34),AVERAGEIF(C:C,C34,F:F),F34),2) -> 283.83 | L34: =ROUNDUP(IF(ISBLANK(G34),AVERAGE(C:C,C34,G:G),G34),0) -> 244 | M34: =K34*L34 -> 69254.52
A35: PROD33 | B35: Modern Wall Clock | C35: Home | D35: Decor | E35: Weiss-Watson | F35: 179.77 | G35: 305 | H35: =IF(LEFT(A35,2)="PROD16","PROD"&TEXT(MID(A35,3,2),"000"),"PROD"&TEXT(MID(A35,5,2),"000")) -> PROD033 | I35: Home | J35: =PROPER(TRIM(B35)) -> Modern Wall Clock | K35: =ROUNDUP(IF(ISBLANK(F35),AVERAGEIF(C:C,C35,F:F),F35),2) -> 179.77 | L35: =ROUNDUP(IF(ISBLANK(G35),AVERAGE(C:C,C35,G:G),G35),0) -> 305 | M35: =K35*L35 -> 54829.85
A36: PROD34 | B36: Gaming Mechanical Keyboard | C36: Electronics | D36: Computer | E36: Lucero LLC | F36: 419.28 | G36: 86 | H36: =IF(LEFT(A36,2)="PROD16","PROD"&TEXT(MID(A36,3,2),"000"),"PROD"&TEXT(MID(A36,5,2),"000")) -> PROD034 | I36: Electronics | J36: =PROPER(TRIM(B36)) -> Gaming Mechanical Keyboard | K36: =ROUNDUP(IF(ISBLANK(F36),AVERAGEIF(C:C,C36,F:F),F36),2) -> 419.28 | L36: =ROUNDUP(IF(ISBLANK(G36),AVERAGE(C:C,C36,G:G),G36),0) -> 86 | M36: =K36*L36 -> 36058.08
A37: PROD35 | B37: Bedroom Table Lamp | C37: Home | D37: Lighting | E37: Jones LLC | F37: 382.22 | G37: 329 | H37: =IF(LEFT(A37,2)="PROD16","PROD"&TEXT(MID(A37,3,2),"000"),"PROD"&TEXT(MID(A37,5,2),"000")) -> PROD035 | I37: Home | J37: =PROPER(TRIM(B37)) -> Bedroom Table Lamp | K37: =ROUNDUP(IF(ISBLANK(F37),AVERAGEIF(C:C,C37,F:F),F37),2) -> 382.22 | L37: =ROUNDUP(IF(ISBLANK(G37),AVERAGE(C:C,C37,G:G),G37),0) -> 329 | M37: =K37*L37 -> 125750.38
A38: PROD36 | B38: Women's Summer Dress | C38: Clothing | D38: Tops | E38: Smith-Mills | F38: 223.43 | G38: 154 | H38: =IF(LEFT(A38,2)="PROD16","PROD"&TEXT(MID(A38,3,2),"000"),"PROD"&TEXT(MID(A38,5,2),"000")) -> PROD036 | I38: Clothing | J38: =PROPER(TRIM(B38)) -> Women'S Summer Dress | K38: =ROUNDUP(IF(ISBLANK(F38),AVERAGEIF(C:C,C38,F:F),F38),2) -> 223.43 | L38: =ROUNDUP(IF(ISBLANK(G38),AVERAGE(C:C,C38,G:G),G38),0) -> 154 | M38: =K38*L38 -> 34408.22
A39: PROD37 | B39: Men's Casual Sneakers | C39: Clothing | D39: Footwear | E39: Hogan-Lee | F39: 353.47 | G39: 214 | H39: =IF(LEFT(A39,2)="PROD16","PROD"&TEXT(MID(A39,3,2),"000"),"PROD"&TEXT(MID(A39,5,2),"000")) -> PROD037 | I39: Clothing | J39: =PROPER(TRIM(B39)) -> Men'S Casual Sneakers | K39: =ROUNDUP(IF(ISBLANK(F39),AVERAGEIF(C:C,C39,F:F),F39),2) -> 353.47 | L39: =ROUNDUP(IF(ISBLANK(G39),AVERAGE(C:C,C39,G:G),G39),0) -> 214 | M39: =K39*L39 -> 75642.58
A40: PROD38 | B40: Sports Water Hydration Pack | C40: Sports | D40: Outdoor | E40: Sims-Smith | F40: 135.61 | G40: 394 | H40: =IF(LEFT(A40,2)="PROD16","PROD"&TEXT(MID(A40,3,2),"000"),"PROD"&TEXT(MID(A40,5,2),"000")) -> PROD038 | I40: Sports | J40: =PROPER(TRIM(B40)) -> Sports Water Hydration Pack | K40: =ROUNDUP(IF(ISBLANK(F40),AVERAGEIF(C:C,C40,F:F),F40),2) -> 135.61 | L40: =ROUNDUP(IF(ISBLANK(G40),AVERAGE(C:C,C40,G:G),G40),0) -> 394 | M40: =K40*L40 -> 53430.34
...

Sheet Store_Dim
A1: Store_ID | B1: Store_Name | C1: Region | D1: City | E1: Store_Type
A2: STORE0 | B2: Rivera-Warner | C2: East | D2: Washingtonfurt | E2: Flagship
A3: STORE1 | B3: Martinez, Adkins and Johnson | C3: North | D3: Danielmouth | E3: Flagship
A4: STORE2 | B4: Black-Horn | C4: South | D4: North Nancyview | E4: Outlet
A5: STORE3 | B5: Johnson-Wright | C5: North | D5: Hoodberg | E5: Outlet
A6: STORE4 | B6: Alexander Group | C6: South | D6: Port Sharon | E6: Online
A7: STORE5 | B7: Gray Ltd | C7: North | D7: New Michaelchester | E7: Outlet
A8: STORE6 | B8: Benson-Elliott | C8: East | D8: Port Josephberg | E8: Online
A9: STORE7 | B9: Martinez-Mullins | C9: South | D9: Williamsfurt | E9: Online
A10: STORE8 | B10: Bean, Jones and Park | C10: West | D10: Thompsonborough | E10: Online
A11: STORE9 | B11: Moore, Padilla and Butler | C11: South | D11: East Johnstad | E11: Flagship
A12: STORE10 | B12: Hill, Wagner and Ballard | C12: East | D12: East Davidville | E12: Online
... A21: STORE19 | B21: Mann-Austin | C21: East | D21: Vasquezborough | E21: Online

Sheet Sales_Fact
A1: Sales_ID | B1: Order_Date | C1: Customer_ID | D1: Product_ID | E1: Store_ID | F1: Quantity | G1: Unit_Price | H1: Discount | I1: Payment_Type | J1: Total_Amount | K1: Clean Order Date | L1: Month | M1: Clean Quantity | N1: Clean Unit Price | O1: Clean Total Amount | P1: Overall Pice | Q1: Discount price | R1: Sales Perfomance | S1: Customer Name | T1: Product Category | U1: Product Name | V1: store region | W1: Loyalty Check | X1: Order range
A2: SALE0 | B2: 45480 | C2: CUST1409 | D2: PROD97 | E2: STORE3 | F2: 1 | G2: 218.04 | H2: 0.09 | I2: Credit Card | J2: 198.4164 | K2: =TEXT(B2,"dd-mm-yyyy") -> 07-07-2024 | L2: =TEXT(Sales_Fact!$B2,"mmm") -> Jul | M2: =IF(ISBLANK(F2),1,F2) -> 1 | N2: =ROUNDUP(IF(ISBLANK(G2),AVERAGE(C:C,G2,G:G),G2),2) -> 218.04 | O2: =M2*N2*(1-H2) -> 198.4164 | P2: =M2*N2 -> 218.04 | Q2: =(P2-O2)/P2 -> 0.09 | R2: =IF(Sales_Fact!$O2>1000,"High","Low") -> Low | S2: =VLOOKUP(C2,Customer_Dim!$A:$N,9,FALSE()) -> Sarah Smith | T2: =VLOOKUP(D2,Product_Dim!$A:$M,3,FALSE()) -> Sports | U2: =VLOOKUP(D2,Product_Dim!$A:$M,2,FALSE()) -> Cricket Bat | V2: =VLOOKUP(E2,Store_Dim!$A:$E,3,FALSE()) -> North | W2: =VLOOKUP(C2,Customer_Dim!$A:$N,13,FALSE()) -> Gold | X2: =IF(F2>3,"High","Low") -> Low
A3: SALE1 | B3: 45285 | C3: CUST1467 | D3: PROD74 | E3: STORE17 | F3: 3 | G3: 104.47 | H3: 0.27 | I3: PayPal | J3: 228.7893 | K3: =TEXT(B3,"dd-mm-yyyy") -> 25-12-2023 | L3: =TEXT(Sales_Fact!$B3,"mmm") -> Dec | M3: =IF(ISBLANK(F3),1,F3) -> 3 | N3: =ROUNDUP(IF(ISBLANK(G3),AVERAGE(C:C,G3,G:G),G3),2) -> 104.47 | O3: =M3*N3*(1-H3) -> 228.7893 | P3: =M3*N3 -> 313.41 | Q3: =(P3-O3)/P3 -> 0.27 | R3: =IF(Sales_Fact!$O3>1000,"High","Low") -> Low | S3: =VLOOKUP(C3,Customer_Dim!$A:$N,9,FALSE()) -> Michael Foley | T3: =VLOOKUP(D3,Product_Dim!$A:$M,3,FALSE()) -> Electronics | U3: =VLOOKUP(D3,Product_Dim!$A:$M,2,FALSE()) -> Bluetooth Car Audio System | V3: =VLOOKUP(E3,Store_Dim!$A:$E,3,FALSE()) -> North | W3: =VLOOKUP(C3,Customer_Dim!$A:$N,13,FALSE()) -> Gold | X3: =IF(F3>3,"High","Low") -> Low
A4: SALE10 | B4: 45335 | C4: CUST1065 | D4: PROD24 | E4: STORE14 | F4: 1 | G4: 278.63 | H4: 0.07 | I4: Credit Card | J4: 259.1259 | K4: =TEXT(B4,"dd-mm-yyyy") -> 13-02-2024 | L4: =TEXT(Sales_Fact!$B4,"mmm") -> Feb | M4: =IF(ISBLANK(F4),1,F4) -> 1 | N4: =ROUNDUP(IF(ISBLANK(G4),AVERAGE(C:C,G4,G:G),G4),2) -> 278.63 | O4: =M4*N4*(1-H4) -> 259.1259 | P4: =M4*N4 -> 278.63 | Q4: =(P4-O4)/P4 -> 0.07 | R4: =IF(Sales_Fact!$O4>1000,"High","Low") -> Low | S4: =VLOOKUP(C4,Customer_Dim!$A:$N,9,FALSE()) -> Michael Thomas | T4: =VLOOKUP(D4,Product_Dim!$A:$M,3,FALSE()) -> Sports | U4: =VLOOKUP(D4,Product_Dim!$A:$M,2,FALSE()) -> Foldable Camping Chair | V4: =VLOOKUP(E4,Store_Dim!$A:$E,3,FALSE()) -> South | W4: =VLOOKUP(C4,Customer_Dim!$A:$N,13,FALSE()) -> Silver | X4: =IF(F4>3,"High","Low") -> Low
A5: SALE100 | B5: 45677 | C5: CUST1369 | D5: PROD33 | E5: STORE5 | F5: 2 | G5: 401.5 | H5: 0.18 | I5: Credit Card | J5: 658.46 | K5: =TEXT(B5,"dd-mm-yyyy") -> 20-01-2025 | L5: =TEXT(Sales_Fact!$B5,"mmm") -> Jan | M5: =IF(ISBLANK(F5),1,F5) -> 2 | N5: =ROUNDUP(IF(ISBLANK(G5),AVERAGE(C:C,G5,G:G),G5),2) -> 401.5 | O5: =M5*N5*(1-H5) -> 658.46 | P5: =M5*N5 -> 803 | Q5: =(P5-O5)/P5 -> 0.18 | R5: =IF(Sales_Fact!$O5>1000,"High","Low") -> Low | S5: =VLOOKUP(C5,Customer_Dim!$A:$N,9,FALSE()) -> Gregory Allen | T5: =VLOOKUP(D5,Product_Dim!$A:$M,3,FALSE()) -> Home | U5: =VLOOKUP(D5,Product_Dim!$A:$M,2,FALSE()) -> Modern Wall Clock | V5: =VLOOKUP(E5,Store_Dim!$A:$E,3,FALSE()) -> North | W5: =VLOOKUP(C5,Customer_Dim!$A:$N,13,FALSE()) -> Platinum | X5: =IF(F5>3,"High","Low") -> Low
A6: SALE1000 | B6: 45456 | C6: CUST1190 | D6: PROD59 | E6: STORE2 | F6: 2 | G6: 909.51 | H6: 0.27 | I6: Credit Card | J6: 1327.8846 | K6: =TEXT(B6,"dd-mm-yyyy") -> 13-06-2024 | L6: =TEXT(Sales_Fact!$B6,"mmm") -> Jun | M6: =IF(ISBLANK(F6),1,F6) -> 2 | N6: =ROUNDUP(IF(ISBLANK(G6),AVERAGE(C:C,G6,G:G),G6),2) -> 909.51 | O6: =M6*N6*(1-H6) -> 1327.8846 | P6: =M6*N6 -> 1819.02 | Q6: =(P6-O6)/P6 -> 0.27 | R6: =IF(Sales_Fact!$O6>1000,"High","Low") -> High | S6: =VLOOKUP(C6,Customer_Dim!$A:$N,9,FALSE()) -> Christopher Stewart | T6: =VLOOKUP(D6,Product_Dim!$A:$M,3,FALSE()) -> Beauty | U6: =VLOOKUP(D6,Product_Dim!$A:$M,2,FALSE()) -> Men's Hair Styling Gel | V6: =VLOOKUP(E6,Store_Dim!$A:$E,3,FALSE()) -> South | W6: =VLOOKUP(C6,Customer_Dim!$A:$N,13,FALSE()) -> Bronze | X6: =IF(F6>3,"High","Low") -> Low
A7: SALE1001 | B7: 45776 | C7: CUST1052 | D7: PROD69 | E7: STORE14 | F7: 4 | G7: 593.84 | H7: 0.24 | I7: PayPal | J7: 1805.2736 | K7: =TEXT(B7,"dd-mm-yyyy") -> 29-04-2025 | L7: =TEXT(Sales_Fact!$B7,"mmm") -> Apr | M7: =IF(ISBLANK(F7),1,F7) -> 4 | N7: =ROUNDUP(IF(ISBLANK(G7),AVERAGE(C:C,G7,G:G),G7),2) -> 593.84 | O7: =M7*N7*(1-H7) -> 1805.2736 | P7: =M7*N7 -> 2375.36 | Q7: =(P7-O7)/P7 -> 0.24 | R7: =IF(Sales_Fact!$O7>1000,"High","Low") -> High | S7: =VLOOKUP(C7,Customer_Dim!$A:$N,9,FALSE()) -> Debra Liu | T7: =VLOOKUP(D7,Product_Dim!$A:$M,3,FALSE()) -> Clothing | U7: =VLOOKUP(D7,Product_Dim!$A:$M,2,FALSE()) -> Men's Sports Shorts | V7: =VLOOKUP(E7,Store_Dim!$A:$E,3,FALSE()) -> South | W7: =VLOOKUP(C7,Customer_Dim!$A:$N,13,FALSE()) -> Bronze | X7: =IF(F7>3,"High","Low") -> High
A8: SALE1002 | B8: 45566 | C8: CUST1109 | D8: PROD73 | E8: STORE10 | F8: 3 | G8: 909.11 | H8: 0.23 | I8: COD | J8: 2100.0441 | K8: =TEXT(B8,"dd-mm-yyyy") -> 01-10-2024 | L8: =TEXT(Sales_Fact!$B8,"mmm") -> Oct | M8: =IF(ISBLANK(F8),1,F8) -> 3 | N8: =ROUNDUP(IF(ISBLANK(G8),AVERAGE(C:C,G8,G:G),G8),2) -> 909.11 | O8: =M8*N8*(1-H8) -> 2100.0441 | P8: =M8*N8 -> 2727.33 | Q8: =(P8-O8)/P8 -> 0.23 | R8: =IF(Sales_Fact!$O8>1000,"High","Low") -> High | S8: =VLOOKUP(C8,Customer_Dim!$A:$N,9,FALSE()) -> Amy Walker | T8: =VLOOKUP(D8,Product_Dim!$A:$M,3,FALSE()) -> Sports | U8: =VLOOKUP(D8,Product_Dim!$A:$M,2,FALSE()) -> Shin Guards – Adult | V8: =VLOOKUP(E8,Store_Dim!$A:$E,3,FALSE()) -> East | W8: =VLOOKUP(C8,Customer_Dim!$A:$N,13,FALSE()) -> Silver | X8: =IF(F8>3,"High","Low") -> Low
A9: SALE1003 | B9: 45542 | C9: CUST1399 | D9: PROD24 | E9: STORE1 | F9: 4 | G9: 996.85 | H9: 0.24 | I9: PayPal | J9: 3030.424 | K9: =TEXT(B9,"dd-mm-yyyy") -> 07-09-2024 | L9: =TEXT(Sales_Fact!$B9,"mmm") -> Sep | M9: =IF(ISBLANK(F9),1,F9) -> 4 | N9: =ROUNDUP(IF(ISBLANK(G9),AVERAGE(C:C,G9,G:G),G9),2) -> 996.85 | O9: =M9*N9*(1-H9) -> 3030.424 | P9: =M9*N9 -> 3987.4 | Q9: =(P9-O9)/P9 -> 0.24 | R9: =IF(Sales_Fact!$O9>1000,"High","Low") -> High | S9: =VLOOKUP(C9,Customer_Dim!$A:$N,9,FALSE()) -> John Donaldson | T9: =VLOOKUP(D9,Product_Dim!$A:$M,3,FALSE()) -> Sports | U9: =VLOOKUP(D9,Product_Dim!$A:$M,2,FALSE()) -> Foldable Camping Chair | V9: =VLOOKUP(E9,Store_Dim!$A:$E,3,FALSE()) -> North | W9: =VLOOKUP(C9,Customer_Dim!$A:$N,13,FALSE()) -> Bronze | X9: =IF(F9>3,"High","Low") -> High
A10: SALE1004 | B10: 45834 | C10: CUST1300 | D10: PROD0 | E10: STORE17 | F10: 1 | G10: 522.69 | H10: 0.06 | I10: COD | J10: 491.3286 | K10: =TEXT(B10,"dd-mm-yyyy") -> 26-06-2025 | L10: =TEXT(Sales_Fact!$B10,"mmm") -> Jun | M10: =IF(ISBLANK(F10),1,F10) -> 1 | N10: =ROUNDUP(IF(ISBLANK(G10),AVERAGE(C:C,G10,G:G),G10),2) -> 522.69 | O10: =M10*N10*(1-H10) -> 491.3286 | P10: =M10*N10 -> 522.69 | Q10: =(P10-O10)/P10 -> 0.06 | R10: =IF(Sales_Fact!$O10>1000,"High","Low") -> Low | S10: =VLOOKUP(C10,Customer_Dim!$A:$N,9,FALSE()) -> Matthew Avery | T10: =VLOOKUP(D10,Product_Dim!$A:$M,3,FALSE()) -> Electronics | U10: =VLOOKUP(D10,Product_Dim!$A:$M,2,FALSE()) -> Brother Laser Printer | V10: =VLOOKUP(E10,Store_Dim!$A:$E,3,FALSE()) -> North | W10: =VLOOKUP(C10,Customer_Dim!$A:$N,13,FALSE()) -> Silver | X10: =IF(F10>3,"High","Low") -> Low
A11: SALE1005 | B11: 45405 | C11: CUST1194 | D11: PROD54 | E11: STORE3 | F11: 3 | G11: 261.05 | H11: 0.12 | I11: PayPal | J11: 689.172 | K11: =TEXT(B11,"dd-mm-yyyy") -> 23-04-2024 | L11: =TEXT(Sales_Fact!$B11,"mmm") -> Apr | M11: =IF(ISBLANK(F11),1,F11) -> 3 | N11: =ROUNDUP(IF(ISBLANK(G11),AVERAGE(C:C,G11,G:G),G11),2) -> 261.05 | O11: =M11*N11*(1-H11) -> 689.172 | P11: =M11*N11 -> 783.15 | Q11: =(P11-O11)/P11 -> 0.12 | R11: =IF(Sales_Fact!$O11>1000,"High","Low") -> Low | S11: =VLOOKUP(C11,Customer_Dim!$A:$N,9,FALSE()) -> Ashley Ferguson | T11: =VLOOKUP(D11,Product_Dim!$A:$M,3,FALSE()) -> Sports | U11: =VLOOKUP(D11,Product_Dim!$A:$M,2,FALSE()) -> Sports Stopwatch Pro | V11: =VLOOKUP(E11,Store_Dim!$A:$E,3,FALSE()) -> North | W11: =VLOOKUP(C11,Customer_Dim!$A:$N,13,FALSE()) -> Gold | X11: =IF(F11>3,"High","Low") -> Low
A12: SALE1006 | B12: 45918 | C12: CUST1087 | D12: PROD23 | E12: STORE17 | F12: 3 | G12: 644.73 | H12: 0.01 | I12: COD | J12: 1914.8481 | K12: =TEXT(B12,"dd-mm-yyyy") -> 18-09-2025 | L12: =TEXT(Sales_Fact!$B12,"mmm") -> Sep | M12: =IF(ISBLANK(F12),1,F12) -> 3 | N12: =ROUNDUP(IF(ISBLANK(G12),AVERAGE(C:C,G12,G:G),G12),2) -> 644.73 | O12: =M12*N12*(1-H12) -> 1914.8481 | P12: =M12*N12 -> 1934.19 | Q12: =(P12-O12)/P12 -> 0.01 | R12: =IF(Sales_Fact!$O12>1000,"High","Low") -> High | S12: =VLOOKUP(C12,Customer_Dim!$A:$N,9,FALSE()) -> Melissa Duffy Md | T12: =VLOOKUP(D12,Product_Dim!$A:$M,3,FALSE()) -> Clothing | U12: =VLOOKUP(D12,Product_Dim!$A:$M,2,FALSE()) -> Men's Formal Shirt | V12: =VLOOKUP(E12,Store_Dim!$A:$E,3,FALSE()) -> North | W12: =VLOOKUP(C12,Customer_Dim!$A:$N,13,FALSE()) -> Bronze | X12: =IF(F12>3,"High","Low") -> Low
A13: SALE1007 | B13: 45217 | C13: CUST1198 | D13: PROD75 | E13: STORE2 | F13: 2 | G13: 541.52 | H13: 0.26 | I13: PayPal | J13: 801.4496 | K13: =TEXT(B13,"dd-mm-yyyy") -> 18-10-2023 | L13: =TEXT(Sales_Fact!$B13,"mmm") -> Oct | M13: =IF(ISBLANK(F13),1,F13) -> 2 | N13: =ROUNDUP(IF(ISBLANK(G13),AVERAGE(C:C,G13,G:G),G13),2) -> 541.52 | O13: =M13*N13*(1-H13) -> 801.4496 | P13: =M13*N13 -> 1083.04 | Q13: =(P13-O13)/P13 -> 0.26 | R13: =IF(Sales_Fact!$O13>1000,"High","Low") -> Low | S13: =VLOOKUP(C13,Customer_Dim!$A:$N,9,FALSE()) -> Wanda Snyder | T13: =VLOOKUP(D13,Product_Dim!$A:$M,3,FALSE()) -> Clothing | U13: =VLOOKUP(D13,Product_Dim!$A:$M,2,FALSE()) -> Women's Ankle Boots | V13: =VLOOKUP(E13,Store_Dim!$A:$E,3,FALSE()) -> South | W13: =VLOOKUP(C13,Customer_Dim!$A:$N,13,FALSE()) -> Bronze | X13: =IF(F13>3,"High","Low") -> Low
... A558: SALE1499 | B558: 45590 | C558: CUST1464 | D558: PROD41 | E558: STORE12 | F558: 2 | G558: 581.19 | H558: 0.07 | I558: COD | J558: 1081.0134 | K558: =TEXT(B558,"dd-mm-yyyy") -> 25-10-2024 | L558: =TEXT(Sales_Fact!$B558,"mmm") -> Oct | M558: =IF(ISBLANK(F558),1,F558) -> 2 | N558: =ROUNDUP(IF(ISBLANK(G558),AVERAGE(C:C,G558,G:G),G558),2) -> 581.19 | O558: =M558*N558*(1-H558) -> 1081.0134 | P558: =M558*N558 -> 1162.38 | Q558: =(P558-O558)/P558 -> 0.07 | R558: =IF(Sales_Fact!$O558>1000,"High","Low") -> High | S558: =VLOOKUP(C558,Customer_Dim!$A:$N,9,FALSE()) -> David Pierce | T558: =VLOOKUP(D558,Product_Dim!$A:$M,3,FALSE()) -> Sports | U558: =VLOOKUP(D558,Product_Dim!$A:$M,2,FALSE()) -> Yoga Exercise Mat | V558: =VLOOKUP(E558,Store_Dim!$A:$E,3,FALSE()) -> North | W558: =VLOOKUP(C558,Customer_Dim!$A:$N,13,FALSE()) -> Platinum | X558: =IF(F558>3,"High","Low") -> Low
A559: SALE15 | B559: 45636 | C559: CUST1435 | D559: PROD36 | E559: STORE9 | G559: 871.34 | H559: 0.04 | I559: COD | J559: 2509.4592 | K559: =TEXT(B559,"dd-mm-yyyy") -> 10-12-2024 | L559: =TEXT(Sales_Fact!$B559,"mmm") -> Dec | M559: =IF(ISBLANK(F559),1,F559) -> 1 | N559: =ROUNDUP(IF(ISBLANK(G559),AVERAGE(C:C,G559,G:G),G559),2) -> 871.34 | O559: =M559*N559*(1-H559) -> 836.4864 | P559: =M559*N559 -> 871.34 | Q559: =(P559-O559)/P559 -> 0.04 | R559: =IF(Sales_Fact!$O559>1000,"High","Low") -> Low | S559: =VLOOKUP(C559,Customer_Dim!$A:$N,9,FALSE()) -> Lindsay Beasley | T559: =VLOOKUP(D559,Product_Dim!$A:$M,3,FALSE()) -> Clothing | U559: =VLOOKUP(D559,Product_Dim!$A:$M,2,FALSE()) -> Women's Summer Dress | V559: =VLOOKUP(E559,Store_Dim!$A:$E,3,FALSE()) -> South | W559: =VLOOKUP(C559,Customer_Dim!$A:$N,13,FALSE()) -> Silver | X559: =IF(F559>3,"High","Low") -> Low
A560: SALE150 | B560: 45433 | C560: CUST1068 | D560: PROD52 | E560: STORE5 | F560: 4 | G560: 355.64 | H560: 0.16 | I560: COD | J560: 1194.9504 | K560: =TEXT(B560,"dd-mm-yyyy") -> 21-05-2024 | L560: =TEXT(Sales_Fact!$B560,"mmm") -> May | M560: =IF(ISBLANK(F560),1,F560) -> 4 | N560: =ROUNDUP(IF(ISBLANK(G560),AVERAGE(C:C,G560,G:G),G560),2) -> 355.64 | O560: =M560*N560*(1-H560) -> 1194.9504 | P560: =M560*N560 -> 1422.56 | Q560: =(P560-O560)/P560 -> 0.16 | R560: =IF(Sales_Fact!$O560>1000,"High","Low") -> High | S560: =VLOOKUP(C560,Customer_Dim!$A:$N,9,FALSE()) -> Mr. Mark Beasley | T560: =VLOOKUP(D560,Product_Dim!$A:$M,3,FALSE()) -> Sports | U560: =VLOOKUP(D560,Product_Dim!$A:$M,2,FALSE()) -> Rugby Ball | V560: =VLOOKUP(E560,Store_Dim!$A:$E,3,FALSE()) -> North | W560: =VLOOKUP(C560,Customer_Dim!$A:$N,13,FALSE()) -> Silver | X560: =IF(F560>3,"High","Low") -> High
A561: SALE1500 | B561: 45618 | C561: CUST1112 | D561: PROD99 | E561: STORE11 | F561: 1 | G561: 736.54 | H561: 0.16 | I561: PayPal | J561: 618.6936 | K561: =TEXT(B561,"dd-mm-yyyy") -> 22-11-2024 | L561: =TEXT(Sales_Fact!$B561,"mmm") -> Nov | M561: =IF(ISBLANK(F561),1,F561) -> 1 | N561: =ROUNDUP(IF(ISBLANK(G561),AVERAGE(C:C,G561,G:G),G561),2) -> 736.54 | O561: =M561*N561*(1-H561) -> 618.6936 | P561: =M561*N561 -> 736.54 | Q561: =(P561-O561)/P561 -> 0.16 | R561: =IF(Sales_Fact!$O561>1000,"High","Low") -> Low | S561: =VLOOKUP(C561,Customer_Dim!$A:$N,9,FALSE()) -> David Cole | T561: =VLOOKUP(D561,Product_Dim!$A:$M,3,FALSE()) -> Home | U561: =VLOOKUP(D561,Product_Dim!$A:$M,2,FALSE()) -> Stainless Steel Cookware Set | V561: =VLOOKUP(E561,Store_Dim!$A:$E,3,FALSE()) -> South | W561: =VLOOKUP(C561,Customer_Dim!$A:$N,13,FALSE()) -> Silver | X561: =IF(F561>3,"High","Low") -> Low
A562: SALE1501 | B562: 45586 | C562: CUST1401 | D562: PROD65 | E562: STORE15 | F562: 1 | G562: 524 | H562: 0.28 | I562: Credit Card | J562: 377.28 | K562: =TEXT(B562,"dd-mm-yyyy") -> 21-10-2024 | L562: =TEXT(Sales_Fact!$B562,"mmm") -> Oct | M562: =IF(ISBLANK(F562),1,F562) -> 1 | N562: =ROUNDUP(IF(ISBLANK(G562),AVERAGE(C:C,G562,G:G),G562),2) -> 524 | O562: =M562*N562*(1-H562) -> 377.28 | P562: =M562*N562 -> 524 | Q562: =(P562-O562)/P562 -> 0.28 | R562: =IF(Sales_Fact!$O562>1000,"High","Low") -> Low | S562: =VLOOKUP(C562,Customer_Dim!$A:$N,9,FALSE()) -> Terry Moses | T562: =VLOOKUP(D562,Product_Dim!$A:$M,3,FALSE()) -> Sports | U562: =VLOOKUP(D562,Product_Dim!$A:$M,2,FALSE()) -> Adjustable Dumbbells 20kg | V562: =VLOOKUP(E562,Store_Dim!$A:$E,3,FALSE()) -> North | W562: =VLOOKUP(C562,Customer_Dim!$A:$N,13,FALSE()) -> Platinum | X562: =IF(F562>3,"High","Low") -> Low
A563: SALE1502 | B563: 45548 | C563: CUST1046 | D563: PROD28 | E563: STORE3 | F563: 4 | G563: 566.09 | H563: 0.28 | I563: COD | J563: 1630.3392 | K563: =TEXT(B563,"dd-mm-yyyy") -> 13-09-2024 | L563: =TEXT(Sales_Fact!$B563,"mmm") -> Sep | M563: =IF(ISBLANK(F563),1,F563) -> 4 | N563: =ROUNDUP(IF(ISBLANK(G563),AVERAGE(C:C,G563,G:G),G563),2) -> 566.09 | O563: =M563*N563*(1-H563) -> 1630.3392 | P563: =M563*N563 -> 2264.36 | Q563: =(P563-O563)/P563 -> 0.28 | R563: =IF(Sales_Fact!$O563>1000,"High","Low") -> High | S563: =VLOOKUP(C563,Customer_Dim!$A:$N,9,FALSE()) -> Michelle Garcia Dds | T563: =VLOOKUP(D563,Product_Dim!$A:$M,3,FALSE()) -> Sports | U563: =VLOOKUP(D563,Product_Dim!$A:$M,2,FALSE()) -> Sports Stopwatch Timer | V563: =VLOOKUP(E563,Store_Dim!$A:$E,3,FALSE()) -> North | W563: =VLOOKUP(C563,Customer_Dim!$A:$N,13,FALSE()) -> Platinum | X563: =IF(F563>3,"High","Low") -> High
A564: SALE1503 | B564: 45772 | C564: CUST1259 | D564: PROD21 | E564: STORE10 | F564: 1 | G564: 251.99 | H564: 0.09 | I564: Credit Card | J564: 229.3109 | K564: =TEXT(B564,"dd-mm-yyyy") -> 25-04-2025 | L564: =TEXT(Sales_Fact!$B564,"mmm") -> Apr | M564: =IF(ISBLANK(F564),1,F564) -> 1 | N564: =ROUNDUP(IF(ISBLANK(G564),AVERAGE(C:C,G564,G:G),G564),2) -> 251.99 | O564: =M564*N564*(1-H564) -> 229.3109 | P564: =M564*N564 -> 251.99 | Q564: =(P564-O564)/P564 -> 0.09 | R564: =IF(Sales_Fact!$O564>1000,"High","Low") -> Low | S564: =VLOOKUP(C564,Customer_Dim!$A:$N,9,FALSE()) -> Beth Allen | T564: =VLOOKUP(D564,Product_Dim!$A:$M,3,FALSE()) -> Home | U564: =VLOOKUP(D564,Product_Dim!$A:$M,2,FALSE()) -> Multi-Purpose Storage Box | V564: =VLOOKUP(E564,Store_Dim!$A:$E,3,FALSE()) -> East | W564: =VLOOKUP(C564,Customer_Dim!$A:$N,13,FALSE()) -> Silver | X564: =IF(F564>3,"High","Low") -> Low
A565: SALE1504 | B565: 45361 | C565: CUST1221 | D565: PROD17 | E565: STORE19 | F565: 1 | G565: 259.2 | H565: 0.27 | I565: COD | J565: 189.216 | K565: =TEXT(B565,"dd-mm-yyyy") -> 10-03-2024 | L565: =TEXT(Sales_Fact!$B565,"mmm") -> Mar | M565: =IF(ISBLANK(F565),1,F565) -> 1 | N565: =ROUNDUP(IF(ISBLANK(G565),AVERAGE(C:C,G565,G:G),G565),2) -> 259.2 | O565: =M565*N565*(1-H565) -> 189.216 | P565: =M565*N565 -> 259.2 | Q565: =(P565-O565)/P565 -> 0.27 | R565: =IF(Sales_Fact!$O565>1000,"High","Low") -> Low | S565: =VLOOKUP(C565,Customer_Dim!$A:$N,9,FALSE()) -> Lisa Young | T565: =VLOOKUP(D565,Product_Dim!$A:$M,3,FALSE()) -> Sports | U565: =VLOOKUP(D565,Product_Dim!$A:$M,2,FALSE()) -> Soccer Training Cone Set | V565: =VLOOKUP(E565,Store_Dim!$A:$E,3,FALSE()) -> East | W565: =VLOOKUP(C565,Customer_Dim!$A:$N,13,FALSE()) -> Platinum | X565: =IF(F565>3,"High","Low") -> Low
A566: SALE1505 | B566: 45235 | C566: CUST1446 | D566: PROD59 | E566: STORE15 | F566: 1 | G566: 935.66 | H566: 0.26 | I566: PayPal | J566: 692.3884 | K566: =TEXT(B566,"dd-mm-yyyy") -> 05-11-2023 | L566: =TEXT(Sales_Fact!$B566,"mmm") -> Nov | M566: =IF(ISBLANK(F566),1,F566) -> 1 | N566: =ROUNDUP(IF(ISBLANK(G566),AVERAGE(C:C,G566,G:G),G566),2) -> 935.66 | O566: =M566*N566*(1-H566) -> 692.3884 | P566: =M566*N566 -> 935.66 | Q566: =(P566-O566)/P566 -> 0.26 | R566: =IF(Sales_Fact!$O566>1000,"High","Low") -> Low | S566: =VLOOKUP(C566,Customer_Dim!$A:$N,9,FALSE()) -> Shannon Turner | T566: =VLOOKUP(D566,Product_Dim!$A:$M,3,FALSE()) -> Beauty | U566: =VLOOKUP(D566,Product_Dim!$A:$M,2,FALSE()) -> Men's Hair Styling Gel | V566: =VLOOKUP(E566,Store_Dim!$A:$E,3,FALSE()) -> North | W566: =VLOOKUP(C566,Customer_Dim!$A:$N,13,FALSE()) -> Silver | X566: =IF(F566>3,"High","Low") -> Low
A567: SALE1506 | B567: 45864 | C567: CUST1469 | D567: PROD35 | E567: STORE8 | F567: 4 | G567: 480.75 | H567: 0.02 | I567: Credit Card | J567: 1884.54 | K567: =TEXT(B567,"dd-mm-yyyy") -> 26-07-2025 | L567: =TEXT(Sales_Fact!$B567,"mmm") -> Jul | M567: =IF(ISBLANK(F567),1,F567) -> 4 | N567: =ROUNDUP(IF(ISBLANK(G567),AVERAGE(C:C,G567,G:G),G567),2) -> 480.75 | O567: =M567*N567*(1-H567) -> 1884.54 | P567: =M567*N567 -> 1923 | Q567: =(P567-O567)/P567 -> 0.02 | R567: =IF(Sales_Fact!$O567>1000,"High","Low") -> High | S567: =VLOOKUP(C567,Customer_Dim!$A:$N,9,FALSE()) -> James Foster | T567: =VLOOKUP(D567,Product_Dim!$A:$M,3,FALSE()) -> Home | U567: =VLOOKUP(D567,Product_Dim!$A:$M,2,FALSE()) -> Bedroom Table Lamp | V567: =VLOOKUP(E567,Store_Dim!$A:$E,3,FALSE()) -> West | W567: =VLOOKUP(C567,Customer_Dim!$A:$N,13,FALSE()) -> Gold | X567: =IF(F567>3,"High","Low") -> High
A568: SALE1507 | B568: 45681 | C568: CUST1369 | D568: PROD81 | E568: STORE15 | F568: 2 | G568: 457.83 | H568: 0.01 | I568: COD | J568: 906.5034 | K568: =TEXT(B568,"dd-mm-yyyy") -> 24-01-2025 | L568: =TEXT(Sales_Fact!$B568,"mmm") -> Jan | M568: =IF(ISBLANK(F568),1,F568) -> 2 | N568: =ROUNDUP(IF(ISBLANK(G568),AVERAGE(C:C,G568,G:G),G568),2) -> 457.83 | O568: =M568*N568*(1-H568) -> 906.5034 | P568: =M568*N568 -> 915.66 | Q568: =(P568-O568)/P568 -> 0.01 | R568: =IF(Sales_Fact!$O568>1000,"High","Low") -> Low | S568: =VLOOKUP(C568,Customer_Dim!$A:$N,9,FALSE()) -> Gregory Allen | T568: =VLOOKUP(D568,Product_Dim!$A:$M,3,FALSE()) -> Sports | U568: =VLOOKUP(D568,Product_Dim!$A:$M,2,FALSE()) -> Badminton Racket Set | V568: =VLOOKUP(E568,Store_Dim!$A:$E,3,FALSE()) -> North | W568: =VLOOKUP(C568,Customer_Dim!$A:$N,13,FALSE()) -> Platinum | X568: =IF(F568>3,"High","Low") -> Low
A569: SALE1508 | B569: 45905 | C569: CUST1164 | D569: PROD48 | E569: STORE14 | F569: 1 | G569: 994.63 | H569: 0.28 | I569: Credit Card | J569: 716.1336 | K569: =TEXT(B569,"dd-mm-yyyy") -> 05-09-2025 | L569: =TEXT(Sales_Fact!$B569,"mmm") -> Sep | M569: =IF(ISBLANK(F569),1,F569) -> 1 | N569: =ROUNDUP(IF(ISBLANK(G569),AVERAGE(C:C,G569,G:G),G569),2) -> 994.63 | O569: =M569*N569*(1-H569) -> 716.1336 | P569: =M569*N569 -> 994.63 | Q569: =(P569-O569)/P569 -> 0.28 | R569: =IF(Sales_Fact!$O569>1000,"High","Low") -> Low | S569: =VLOOKUP(C569,Customer_Dim!$A:$N,9,FALSE()) -> Daniel Rivas | T569: =VLOOKUP(D569,Product_Dim!$A:$M,3,FALSE()) -> Electronics | U569: =VLOOKUP(D569,Product_Dim!$A:$M,2,FALSE()) -> Car Dashboard Phone Holder | V569: =VLOOKUP(E569,Store_Dim!$A:$E,3,FALSE()) -> South | W569: =VLOOKUP(C569,Customer_Dim!$A:$N,13,FALSE()) -> Silver | X569: =IF(F569>3,"High","Low") -> Low
A570: SALE1509 | B570: 45765 | C570: CUST1245 | D570: PROD90 | E570: STORE0 | F570: 3 | G570: 65.57 | H570: 0.3 | I570: COD | J570: 137.697 | K570: =TEXT(B570,"dd-mm-yyyy") -> 18-04-2025 | L570: =TEXT(Sales_Fact!$B570,"mmm") -> Apr | M570: =IF(ISBLANK(F570),1,F570) -> 3 | N570: =ROUNDUP(IF(ISBLANK(G570),AVERAGE(C:C,G570,G:G),G570),2) -> 65.57 | O570: =M570*N570*(1-H570) -> 137.697 | P570: =M570*N570 -> 196.71 | Q570: =(P570-O570)/P570 -> 0.3 | R570: =IF(Sales_Fact!$O570>1000,"High","Low") -> Low | S570: =VLOOKUP(C570,Customer_Dim!$A:$N,9,FALSE()) -> Laura Soto | T570: =VLOOKUP(D570,Product_Dim!$A:$M,3,FALSE()) -> Electronics | U570: =VLOOKUP(D570,Product_Dim!$A:$M,2,FALSE()) -> Gaming Mouse Pad XL | V570: =VLOOKUP(E570,Store_Dim!$A:$E,3,FALSE()) -> East | W570: =VLOOKUP(C570,Customer_Dim!$A:$N,13,FALSE()) -> Platinum | X570: =IF(F570>3,"High","Low") -> Low
